Workbook

Sheet Data_Input
A1: DATA INPUT - historical financials. Fixed row keys in column A; one column per year. A Python extractor should write ONLY this tab. (You may hide this tab.)
A3: key | B3: label | C3: FY2021 | D3: FY2022 | E3: FY2023 | F3: FY2024 | G3: FY2025
A4: -- income_statement --
A5: revenue | B5: Revenue | C5: 117.929 | D5: 116.609 | E5: 134.902 | F5: 164.501 | G5: 200.966
A6: cogs | B6: Cogs | C6: 22.649 | D6: 25.249 | E6: 25.959 | F6: 30.161 | G6: 36.175
A7: salaries_and_benefits | B7: Salaries And Benefits | C7: 20.6072 | D7: 30.4203 | E7: 31.5663 | F7: 33.4059 | G7: 44.2697
A8: rent_and_overhead | B8: Rent And Overhead | C8: 19.9528 | D8: 23.3097 | E8: 19.4477 | F8: 16.0561 | G8: 18.6293
A9: d_and_a | B9: D And A | C9: 7.967 | D9: 8.686 | E9: 11.178 | F9: 15.498 | G9: 18.616
A10: interest | B10: Interest | C10: 0.023 | D10: 0.185 | E10: 0.446 | F10: 0.715 | G10: 1.165
A11: taxes | B11: Taxes | C11: 7.914 | D11: 5.619 | E11: 8.33 | F11: 8.303 | G11: 25.474
A12: -- balance_sheet --
A13: cash | B13: Cash | C13: 54.773 | D13: 46.939 | E13: 71.544 | F13: 83.885 | G13: 109.116
A14: accounts_receivable | B14: Accounts Receivable | C14: 14.039 | D14: 13.466 | E14: 16.169 | F14: 16.994 | G14: 19.769
A15: inventory | B15: Inventory | C15: 0 | D15: 0 | E15: 0 | F15: 0 | G15: 0
A16: ppe | B16: Ppe | C16: 97.175 | D16: 125.322 | E16: 141.91 | F16: 175.175 | G16: 237.136
A17: accounts_payable | B17: Accounts Payable | C17: 27.235 | D17: 33.423 | E17: 39.221 | F17: 44.357 | G17: 64.881
A18: debt | B18: Debt | C18: 13.873 | D18: 26.591 | E18: 37.234 | F18: 49.06 | G18: 83.897
A19: equity_capital | B19: Equity Capital | C19: 55.118 | D19: 60.914 | E19: 71.098 | F19: 80.131 | G19: 96.064
A20: retained_earnings | B20: Retained Earnings | C20: 69.761 | D20: 64.799 | E20: 82.07 | F20: 102.506 | G20: 121.179
A21: -- schedules --
A22: capex | B22: Capex | C22: 18.567 | D22: 31.431 | E22: 27.266 | F22: 37.256 | G22: 69.691
A23: debt_issuance | B23: Debt Issuance | C23: -0.663 | D23: 9.071 | E23: 7.397 | F23: 8.463 | G23: 27.382
A24: equity_issued | B24: Equity Issued | C24: -44.537 | D24: -31.551 | E24: -26.786 | F24: -30.125 | G24: -26.248
A25: -- opening_balances --
A26: ppe_opening_first | B26: Ppe Opening First | C26: 86.575
A27: debt_opening_first | B27: Debt Opening First | C27: 14.536
A28: nol_opening | B28: Nol Opening | C28: 0

Sheet Financial Model & DCF
A1: Meta Platforms, Inc. (NASDAQ: META) | D1: Historical Results | I1: Forecast Period
D2: 2021 | E2: 2022 | F2: 2023 | G2: 2024 | H2: 2025 | I2: 2026 | J2: 2027 | K2: 2028 | L2: 2029 | M2: 2030 | N2: 2031 | O2: 2032 | P2: 2033 | Q2: 2034 | R2: 2035
A3: Balance Sheet Check | D3: =IF(ABS(D60)<0.005,"OK","ERROR") | E3: =IF(ABS(E60)<0.005,"OK","ERROR") | F3: =IF(ABS(F60)<0.005,"OK","ERROR") | G3: =IF(ABS(G60)<0.005,"OK","ERROR") | H3: =IF(ABS(H60)<0.005,"OK","ERROR") | I3: =IF(ABS(I60)<0.005,"OK","ERROR") | J3: =IF(ABS(J60)<0.005,"OK","ERROR") | K3: =IF(ABS(K60)<0.005,"OK","ERROR") | ... R3: =IF(ABS(R60)<0.005,"OK","ERROR")
A4: All figures in USD billions unless noted | per-share values in USD | E4: Scenario: Prices 17-Jul-2026 (live quote). rf 4.55% = US 10Y as-of 17-Jul-2026 (was 4.30% - refreshed); terminal g = rf per Damodaran convention. AUDITED CONVENTIONS: per-share = equity / TODAY'S diluted count; capital returns modeled as equity outflows (count constant - no double count); treasury line includes ST+LT investments (in the equity bridge; their income excluded from FCF). DAMODARAN 10-YR: growth 14%->4.5%, opex leverage 31.7%->28%, AI capex $75-80B->65B, WACC 9.9%->8.7%, terminal g=rf, exit 13x. Returns $32B/yr. FY25 tax 29.6% distorted by deferred one-offs; modeled 20%. Consensus $828. Year-1 D&A +21% vs FY2025 is deliberate: management guides accelerating depreciation as the AI-datacenter buildout enters service.
A5: Assumptions | E5: Corporate actions: none found - searched 2026-07-16; buybacks modeled as capital returns. NEWS SCAN 2026-07-19: stock +21% month-to-date on AI infrastructure narrative; Iris in-house AI chip to production Sept-2026, plan to double compute to 14GW; management pivoting to SELL excess compute externally (revenue line NOT in this deck - upside). Forward P/E lags Mag-7 peers. No dilutive actions.
A7: Key Assumptions
A8: Revenue Growth (% Change) | E8: =E26/D26-1 | F8: =F26/E26-1 | G8: =G26/F26-1 | H8: =H26/G26-1 | I8: 0.14 | J8: 0.13 | K8: 0.12 | L8: 0.11 | M8: 0.1 | N8: 0.09 | O8: 0.08 | P8: 0.07 | Q8: 0.06 | R8: 0.045
A9: Cost of Goods Sold (% of Revenue) | D9: =D27/D26 | E9: =E27/E26 | F9: =F27/F26 | G9: =G27/G26 | H9: =H27/H26 | I9: 0.18 | J9: 0.18 | K9: 0.18 | L9: 0.18 | M9: 0.18 | N9: 0.18 | O9: 0.18 | P9: 0.18 | Q9: 0.18 | R9: 0.18
A10: Research & Development (% of Revenue) | D10: =D30/D26 | E10: =E30/E26 | F10: =F30/F26 | G10: =G30/G26 | H10: =H30/H26 | I10: 0.2231 | J10: 0.2196 | K10: 0.2161 | L10: 0.2126 | M10: 0.209 | N10: 0.2055 | O10: 0.2027 | P10: 0.1999 | Q10: 0.1978 | R10: 0.1971
A11: Marketing & Sales + General & Administrative (USD billions) | D11: =D31 | E11: =E31 | F11: =F31 | G11: =G31 | H11: =H31 | I11: 21.51 | J11: 23.92 | K11: 26.36 | L11: 28.79 | M11: 31.14 | N11: 33.37 | O11: 35.55 | P11: 37.5 | Q11: 39.34 | R11: 40.96
A12: Depreciation & Amortization (% of PP&E) | D12: =D32/D96 | E12: =E32/E96 | F12: =F32/F96 | G12: =G32/G96 | H12: =H32/H96 | I12: 0.095 | J12: 0.095 | K12: 0.095 | L12: 0.095 | M12: 0.095 | N12: 0.095 | O12: 0.095 | P12: 0.095 | Q12: 0.095 | R12: 0.095
A13: Interest (% of Debt) | D13: =D33/AVERAGE(D102,D104) | E13: =E33/AVERAGE(E102,E104) | F13: =F33/AVERAGE(F102,F104) | G13: =G33/AVERAGE(G102,G104) | H13: =H33/AVERAGE(H102,H104) | I13: 0.035 | J13: 0.035 | K13: 0.035 | L13: 0.035 | M13: 0.035 | N13: 0.035 | O13: 0.035 | P13: 0.035 | Q13: 0.035 | R13: 0.035
A14: Tax Rate (% of Earnings Before Tax) | D14: =IF(D35=0,0,D37/D35) | E14: =IF(E35=0,0,E37/E35) | F14: =IF(F35=0,0,F37/F35) | G14: =IF(G35=0,0,G37/G35) | H14: =IF(H35=0,0,H37/H35) | I14: 0.2 | J14: 0.2 | K14: 0.2 | L14: 0.2 | M14: 0.2 | N14: 0.2 | O14: 0.2 | P14: 0.2 | Q14: 0.2 | R14: 0.2
A15: Accounts Receivable (Days) | D15: =D45/D26*D21 | E15: =E45/E26*E21 | F15: =F45/F26*F21 | G15: =G45/G26*G21 | H15: =H45/H26*H21 | I15: 36 | J15: 36 | K15: 36 | L15: 36 | M15: 36 | N15: 36 | O15: 36 | P15: 36 | Q15: 36 | R15: 36
A16: Inventory (Days) | D16: =D46/D27*D21 | E16: =E46/E27*E21 | F16: =F46/F27*F21 | G16: =G46/G27*G21 | H16: =H46/H27*H21 | I16: 0 | J16: 0 | K16: 0 | L16: 0 | M16: 0 | N16: 0 | O16: 0 | P16: 0 | Q16: 0 | R16: 0
A17: Accounts Payable (Days) | D17: =D51/D27*D21 | E17: =E51/E27*E21 | F17: =F51/F27*F21 | G17: =G51/G27*G21 | H17: =H51/H27*H21 | I17: 654 | J17: 654 | K17: 654 | L17: 654 | M17: 654 | N17: 654 | O17: 654 | P17: 654 | Q17: 654 | R17: 654
A18: Capital Expenditures (USD billions) | D18: =D97 | E18: =E97 | F18: =F97 | G18: =G97 | H18: =H97 | I18: 75 | J18: 80 | K18: 80 | L18: 78 | M18: 75 | N18: 72 | O18: 70 | P18: 68 | Q18: 66 | R18: 65
A19: Debt Issuance (Repayment) (USD billions) | D19: =D103 | E19: =E103 | F19: =F103 | G19: =G103 | H19: =H103 | I19: 0 | J19: 0 | K19: 0 | L19: 0 | M19: 0 | N19: 0 | O19: 0 | P19: 0 | Q19: 0 | R19: 0
A20: Equity Issued (Repaid) (USD billions) | D20: =D77 | E20: =E77 | F20: =F77 | G20: =G77 | H20: =H77 | I20: -32 | J20: -32 | K20: -32 | L20: -32 | M20: -32 | N20: -32 | O20: -32 | P20: -32 | Q20: -32 | R20: -32
A21: Days in Period | D21: 365 | E21: 365 | F21: 365 | G21: 365 | H21: 365 | I21: 365 | J21: 365 | K21: 365 | L21: 365 | M21: 365 | N21: 365 | O21: 365 | P21: 365 | Q21: 365 | R21: 365
A24: Income Statement
A26: Revenue | D26: =Data_Input!C5 | E26: =Data_Input!D5 | F26: =Data_Input!E5 | G26: =Data_Input!F5 | H26: =Data_Input!G5 | I26: =H26*(1+I8) | J26: =I26*(1+J8) | K26: =J26*(1+K8) | L26: =K26*(1+L8) | M26: =L26*(1+M8) | N26: =M26*(1+N8) | O26: =N26*(1+O8) | P26: =O26*(1+P8) | ... R26: =Q26*(1+R8)
A27: Cost of Goods Sold (COGS) | D27: =Data_Input!C6 | E27: =Data_Input!D6 | F27: =Data_Input!E6 | G27: =Data_Input!F6 | H27: =Data_Input!G6 | I27: =I26*I9 | J27: =J26*J9 | K27: =K26*K9 | L27: =L26*L9 | M27: =M26*M9 | N27: =N26*N9 | O27: =O26*O9 | P27: =P26*P9 | ... R27: =R26*R9
A28: Gross Profit | D28: =D26-D27 | E28: =E26-E27 | F28: =F26-F27 | G28: =G26-G27 | H28: =H26-H27 | I28: =I26-I27 | J28: =J26-J27 | K28: =K26-K27 | ... R28: =R26-R27
A29: Expenses
A30: Research & Development | D30: =Data_Input!C7 | E30: =Data_Input!D7 | F30: =Data_Input!E7 | G30: =Data_Input!F7 | H30: =Data_Input!G7 | I30: =I26*I10 | J30: =J26*J10 | K30: =K26*K10 | L30: =L26*L10 | M30: =M26*M10 | N30: =N26*N10 | O30: =O26*O10 | P30: =P26*P10 | ... R30: =R26*R10
A31: Marketing & Sales + General & Administrative | D31: =Data_Input!C8 | E31: =Data_Input!D8 | F31: =Data_Input!E8 | G31: =Data_Input!F8 | H31: =Data_Input!G8 | I31: =I11 | J31: =J11 | K31: =K11 | L31: =L11 | M31: =M11 | N31: =N11 | O31: =O11 | P31: =P11 | ... R31: =R11
A32: Depreciation & Amortization | D32: =Data_Input!C9 | E32: =Data_Input!D9 | F32: =Data_Input!E9 | G32: =Data_Input!F9 | H32: =Data_Input!G9 | I32: =I12*I96 | J32: =J12*J96 | K32: =K12*K96 | L32: =L12*L96 | M32: =M12*M96 | N32: =N12*N96 | O32: =O12*O96 | P32: =P12*P96 | ... R32: =R12*R96
A33: Interest | D33: =Data_Input!C10 | E33: =Data_Input!D10 | F33: =Data_Input!E10 | G33: =Data_Input!F10 | H33: =Data_Input!G10 | I33: =I13*AVERAGE(I102,I104) | J33: =J13*AVERAGE(J102,J104) | K33: =K13*AVERAGE(K102,K104) | L33: =L13*AVERAGE(L102,L104) | M33: =M13*AVERAGE(M102,M104) | N33: =N13*AVERAGE(N102,N104) | O33: =O13*AVERAGE(O102,O104) | P33: =P13*AVERAGE(P102,P104) | ... R33: =R13*AVERAGE(R102,R104)
A34: Total Expenses | D34: =SUM(D30:D33) | E34: =SUM(E30:E33) | F34: =SUM(F30:F33) | G34: =SUM(G30:G33) | H34: =SUM(H30:H33) | I34: =SUM(I30:I33) | J34: =SUM(J30:J33) | K34: =SUM(K30:K33) | ... R34: =SUM(R30:R33)
A35: Earnings Before Tax | D35: =D28-D34 | E35: =E28-E34 | F35: =F28-F34 | G35: =G28-G34 | H35: =H28-H34 | I35: =I28-I34 | J35: =J28-J34 | K35: =K28-K34 | ... R35: =R28-R34
A37: Taxes | D37: =Data_Input!C11 | E37: =Data_Input!D11 | F37: =Data_Input!E11 | G37: =Data_Input!F11 | H37: =Data_Input!G11 | I37: =MAX(I35-I109,0)*I14 | J37: =MAX(J35-J109,0)*J14 | K37: =MAX(K35-K109,0)*K14 | L37: =MAX(L35-L109,0)*L14 | M37: =MAX(M35-M109,0)*M14 | N37: =MAX(N35-N109,0)*N14 | O37: =MAX(O35-O109,0)*O14 | P37: =MAX(P35-P109,0)*P14 | ... R37: =MAX(R35-R109,0)*R14
A38: Net Earnings | D38: =D35-D37 | E38: =E35-E37 | F38: =F35-F37 | G38: =G35-G37 | H38: =H35-H37 | I38: =I35-I37 | J38: =J35-J37 | K38: =K35-K37 | ... R38: =R35-R37
A41: Balance Sheet
A43: Assets
A44: Cash | D44: =Data_Input!C13 | E44: =Data_Input!D13 | F44: =Data_Input!E13 | G44: =Data_Input!F13 | H44: =Data_Input!G13 | I44: =I82 | J44: =J82 | K44: =K82 | L44: =L82 | M44: =M82 | N44: =N82 | O44: =O82 | P44: =P82 | ... R44: =R82
A45: Accounts Receivable | D45: =Data_Input!C14 | E45: =Data_Input!D14 | F45: =Data_Input!E14 | G45: =Data_Input!F14 | H45: =Data_Input!G14 | I45: =I15/I21*I26 | J45: =J15/J21*J26 | K45: =K15/K21*K26 | L45: =L15/L21*L26 | M45: =M15/M21*M26 | N45: =N15/N21*N26 | O45: =O15/O21*O26 | P45: =P15/P21*P26 | ... R45: =R15/R21*R26
A46: Inventory | D46: =Data_Input!C15 | E46: =Data_Input!D15 | F46: =Data_Input!E15 | G46: =Data_Input!F15 | H46: =Data_Input!G15 | I46: =I16/I21*I27 | J46: =J16/J21*J27 | K46: =K16/K21*K27 | L46: =L16/L21*L27 | M46: =M16/M21*M27 | N46: =N16/N21*N27 | O46: =O16/O21*O27 | P46: =P16/P21*P27 | ... R46: =R16/R21*R27
A47: Property & Equipment | D47: =Data_Input!C16 | E47: =Data_Input!D16 | F47: =Data_Input!E16 | G47: =Data_Input!F16 | H47: =Data_Input!G16 | I47: =I99 | J47: =J99 | K47: =K99 | L47: =L99 | M47: =M99 | N47: =N99 | O47: =O99 | P47: =P99 | ... R47: =R99
A48: Total Assets | D48: =SUM(D44:D47) | E48: =SUM(E44:E47) | F48: =SUM(F44:F47) | G48: =SUM(G44:G47) | H48: =SUM(H44:H47) | I48: =SUM(I44:I47) | J48: =SUM(J44:J47) | K48: =SUM(K44:K47) | ... R48: =SUM(R44:R47)
...
